Workbook

Sheet Tasa Cambio
B2: Tasas de Cambio del dólar de Referencia del Mercado Spot, Promedio Mensual *
B4: 2026
B5: Mes | C5: Compra | D5: Venta | E5: Promedio
B6: Enero | E6: =AVERAGE(C6:D6) -> #DIV/0!
B7: Febrero | E7: =AVERAGE(C7:D7) -> #DIV/0!
B8: Marzo | E8: =AVERAGE(C8:D8) -> #DIV/0!
B9: Abril | E9: =AVERAGE(C9:D9) -> #DIV/0!
B10: Mayo | E10: =AVERAGE(C10:D10) -> #DIV/0!
B11: Junio | E11: =AVERAGE(C11:D11) -> #DIV/0!
B12: Julio | E12: =AVERAGE(C12:D12) -> #DIV/0!
B13: Agosto | E13: =AVERAGE(C13:D13) -> #DIV/0!
B14: Sept. | E14: =AVERAGE(C14:D14) -> #DIV/0!
B15: Oct. | E15: =AVERAGE(C15:D15) -> #DIV/0!
B16: Nov. | E16: =AVERAGE(C16:D16) -> #DIV/0!
B17: Dic. | E17: =AVERAGE(C17:D17) -> #DIV/0!

Sheet Comparativos
A2: 2020
A3: REAL SUPERMERCADO | D3: REVERSE | G3: BM cargo | J3: RESTAURANTES | M3: LAVANDERIA | P3: FLORISTERIA | S3: VINOS
A4: enero | B4: 70471.54 | D4: enero | E4: 14320 | G4: enero | H4: 7798.39 | J4: enero | K4: 54080.73 | M4: enero | N4: 4879.3 | P4: enero | S4: enero
A5: febrero | B5: 34703.6 | D5: febrero | E5: 8920 | G5: febrero | H5: 12789.73 | J5: febrero | K5: 39864.6 | M5: febrero | N5: 6449.3 | P5: febrero | S5: febrero
A6: marzo | B6: 46442.17 | D6: marzo | E6: 18880 | G6: marzo | H6: 9208.5 | J6: marzo | K6: 45267.26 | M6: marzo | N6: 6914.2 | P6: marzo | Q6: 1800 | S6: marzo | T6: 0
A7: abril | B7: 88265.34 | D7: abril | E7: 5925 | G7: abril | H7: 4750.33 | J7: abril | K7: 36635.77 | M7: abril | N7: 6613.9 | P7: abril | Q7: =1750+600+1875 -> 4225 | S7: abril | T7: 20726.13
A8: mayo | B8: 79934.01 | D8: mayo | E8: 0 | G8: mayo | H8: 7517.04 | J8: mayo | K8: 7136 | M8: mayo | N8: 0 | P8: mayo | Q8: =960+1200+300+2500+4250 -> 9210 | S8: mayo | T8: 25186.98
A9: junio | B9: 39129.49 | D9: junio | E9: 0 | G9: junio | H9: 16805.05 | J9: junio | K9: 19757.1 | M9: junio | N9: 0 | P9: junio | Q9: =1570+2380+2410+359+1458 -> 8177 | S9: junio | T9: 34350.99
A10: julio | B10: 83414.93 | D10: julio | E10: 19970 | G10: julio | H10: 6238.75 | J10: julio | K10: 4324.7 | M10: julio | N10: 6478.2 | P10: julio | Q10: 9227 | S10: julio | T10: 23340.01
A11: agosto | B11: 97585.87 | D11: agosto | E11: 2290 | G11: Julio | H11: 10703.56 | J11: agosto | K11: =4872 -> 4872 | M11: agosto | N11: 2006 | P11: agosto | Q11: 5310 | S11: agosto | T11: 32122.08
A12: septiembre | B12: 41268.42 | D12: septiembre | E12: 7280 | G12: septiembre | H12: 8496.14 | J12: septiembre | K12: 33644.25 | M12: septiembre | N12: 3392.5 | P12: septiembre | Q12: 8113 | S12: septiembre | T12: 44081.25
A13: octubre | B13: 69702.91 | D13: octubre | E13: 10350 | G13: octubre | H13: 13045.04 | J13: octubre | K13: 11198.63 | M13: octubre | N13: 14975.38 | P13: octubre | Q13: 6212 | S13: octubre | T13: 0
A14: noviembre | B14: 69222.51 | D14: noviembre | E14: 900 | G14: noviembre | H14: 17292.62 | J14: noviembre | K14: 44169.8 | M14: noviembre | N14: 3599 | P14: noviembre | Q14: 8858 | S14: noviembre | T14: 7937.17
A15: diciembre | B15: 46087.78 | D15: diciembre | E15: 21730 | G15: diciembre | H15: 18628.3 | J15: diciembre | K15: 38270.87 | M15: diciembre | N15: 7437.67 | P15: diciembre | Q15: 5786 | S15: diciembre | T15: 22323.81
A16: Total: | B16: =SUM(B4:B15) -> 766228.57 | D16: Total: | E16: =SUM(E4:E15) -> 110565 | G16: Total: | H16: =SUM(H4:H15) -> 133273.45 | J16: Total: | K16: =SUM(K4:K15) -> 339221.71 | M16: Total: | N16: =SUM(N4:N15) -> 62745.45 | P16: Total: | Q16: =SUM(Q4:Q15) -> 66918 | S16: Total: | T16: =SUM(T4:T15) -> 210068.42
A17: Average | B17: =B16/12 -> 63852.381 | D17: Average | E17: =E16/12 -> 9213.75 | G17: Average | H17: =H16/12 -> 11106.121 | J17: Average | K17: =K16/12 -> 28268.476 | M17: Average | N17: =N16/12 -> 5228.7875 | P17: Average | Q17: =Q16/10 -> 6691.8 | S17: Average | T17: =T16/12 -> 17505.702
A20: 2021
A21: REAL SUPERMERCADO | D21: REVERSE | G21: BM cargo | J21: RESTAURANTES | M21: LAVANDERIA | P21: FLORISTERIA | S21: VINOS
A22: enero | B22: 65367.29 | D22: enero | E22: 1367.5 | G22: enero | H22: 22550.46 | J22: enero | K22: 31531.29 | M22: enero | N22: 4875.06 | P22: enero | Q22: 12382 | S22: enero | T22: 25580.02
A23: febrero | B23: 39603.23 | D23: febrero | E23: 10600 | G23: febrero | H23: 3324.98 | J23: febrero | K23: 22857.2 | M23: febrero | N23: 5845.84 | P23: febrero | Q23: 8856 | S23: febrero | T23: 3817.5
A24: marzo | B24: 55363.88 | D24: marzo | E24: 17185 | G24: marzo | H24: 6741.36 | J24: marzo | K24: 46780.26 | M24: marzo | N24: 6354.39 | P24: marzo | Q24: 3900 | S24: marzo | T24: 33930.6
A25: abril | B25: 43563.61 | D25: abril | E25: 5400 | G25: abril | H25: 10037.41 | J25: abril | K25: 55780.9 | M25: abril | N25: 9285.07 | P25: abril | Q25: 5843 | S25: abril | T25: 0
A26: mayo | B26: 94643.31 | D26: mayo | E26: 18605 | G26: mayo | H26: 11157.5 | J26: mayo | K26: 10970.84 | M26: mayo | N26: 5894.93 | P26: mayo | Q26: 11200 | S26: mayo | T26: 3159
A27: junio | B27: 86029.57 | D27: junio | E27: 16200 | G27: junio | H27: 11302 | J27: junio | K27: 38133.58 | M27: junio | N27: 8680.91 | P27: junio | Q27: 6106 | S27: junio | T27: 0
A28: julio | B28: 39173.34 | D28: julio | E28: 5500 | G28: julio | H28: 7363.57 | J28: julio | K28: 19026.48 | M28: julio | N28: 7854.84 | P28: julio | Q28: 6450 | S28: julio | T28: 19495.97
A29: agosto | B29: 69077.78 | D29: agosto | E29: 3110 | G29: Julio | H29: 6502.63 | J29: agosto | K29: 29905.8 | M29: agosto | N29: 7286.27 | P29: agosto | Q29: 7057 | S29: agosto | T29: 49755.43
A30: septiembre | B30: 45143.07 | D30: septiembre | E30: 17640 | G30: septiembre | H30: 10942.31 | J30: septiembre | K30: 45844.69 | M30: septiembre | N30: 12249.62 | P30: septiembre | Q30: 11870 | S30: septiembre | T30: 33793.58
A31: octubre | B31: 75632.04 | D31: octubre | E31: 10710 | G31: octubre | H31: 15564.05 | J31: octubre | K31: 65834.7 | M31: octubre | N31: 11968.4 | P31: octubre | Q31: 3249 | S31: octubre | T31: 15867.5
A32: noviembre | B32: 49909.85 | D32: noviembre | E32: 25030 | G32: noviembre | H32: 3870.46 | J32: noviembre | K32: 32291.51 | M32: noviembre | N32: 7285.44 | P32: noviembre | Q32: 1460 | S32: noviembre | T32: 4970
A33: diciembre | B33: 82665.39 | D33: diciembre | E33: 10130 | G33: diciembre | H33: 11648.35 | J33: diciembre | K33: 82799.6 | M33: diciembre | N33: 14455.17 | P33: diciembre | Q33: 1749 | S33: diciembre | T33: 30490
A34: Total: | B34: =SUM(B22:B32) -> 663506.97 | D34: Total: | E34: =SUM(E22:E32) -> 131347.5 | G34: Total: | H34: =SUM(H22:H32) -> 109356.73 | J34: Total: | K34: =SUM(K22:K32) -> 398957.25 | M34: Total: | N34: =SUM(N22:N32) -> 87580.77 | P34: Total: | Q34: =SUM(Q22:Q32) -> 78373 | S34: Total: | T34: =SUM(T22:T32) -> 190369.6
A35: Average | B35: =B34/12 -> 55292.247 | D35: Average | E35: =E34/12 -> 10945.625 | G35: Average | H35: =H34/12 -> 9113.0608 | J35: Average | K35: =K34/12 -> 33246.438 | M35: Average | N35: =N34/12 -> 7298.3975 | P35: Average | Q35: =Q34/12 -> 6531.0833 | S35: Average | T35: =T34/12 -> 15864.133
A38: 2022
A39: REAL SUPERMERCADO | D39: REVERSE | G39: BM cargo | J39: RESTAURANTES | M39: LAVANDERIA | P39: FLORISTERIA | S39: VINOS | V39: SIL ESTHETIC SPA | Y39: TRAVEL CREDIT BA
A40: enero | B40: 48800.98 | D40: enero | E40: 15775 | G40: enero | H40: 10338.84 | J40: enero | K40: 73411.5 | M40: enero | N40: 9080.81 | P40: enero | Q40: 15189 | S40: enero | T40: 7150 | V40: enero | W40: 0 | Y40: enero | Z40: 0
A41: febrero | B41: 62525.88 | D41: febrero | E41: 18425 | G41: febrero | H41: 10142.06 | J41: febrero | K41: 26048.05 | M41: febrero | N41: 6580.86 | P41: febrero | Q41: 13565 | S41: febrero | T41: 7815.15 | V41: febrero | W41: 0 | Y41: febrero | Z41: -404.01
A42: marzo | B42: 48258.99 | D42: marzo | E42: 28115 | G42: marzo | H42: 3535.74 | J42: marzo | K42: 44165.88 | M42: marzo | N42: 7756.14 | P42: marzo | Q42: 9830 | S42: marzo | T42: 19149.39 | V42: marzo | W42: 44300 | Y42: marzo | Z42: 0
A43: abril | B43: 63960.35 | D43: abril | E43: 21360 | G43: abril | H43: 3245.96 | J43: abril | K43: 67334.35 | M43: abril | N43: 901.53 | P43: abril | Q43: 12459 | S43: abril | T43: 5799.98 | V43: abril | W43: 0 | Y43: abril | Z43: -1256.74
A44: mayo | B44: 57396.77 | D44: mayo | E44: 13615 | G44: mayo | H44: 7214.81 | J44: mayo | K44: 42020.25 | M44: mayo | N44: 3071.54 | P44: mayo | Q44: 3945 | S44: mayo | T44: 0 | V44: mayo | W44: 0 | Y44: mayo | Z44: 0
A45: junio | B45: 53581.12 | D45: junio | E45: 26535 | G45: junio | H45: 7940.93 | J45: junio | K45: 64215.15 | M45: junio | N45: 5531.84 | P45: junio | Q45: 6959 | S45: junio | T45: 34419.96 | V45: junio | W45: 0 | Y45: junio | Z45: 0
...

Sheet 2025
B1: 45658 | D1: 45689 | F1: 45717 | H1: 45748 | J1: 45778 | L1: 45809 | N1: 45839 | P1: 45870 | R1: 45901 | T1: 45931 | V1: 45962 | X1: 45992 | Z1: TOTAL
A2: CASA | B2: RD$ | C2: US$ | D2: RD$ | E2: US$ | F2: RD$ | G2: US$ | H2: RD$ | I2: US$ | J2: RD$ | K2: US$ | L2: RD$ | M2: US$ | N2: RD$ | O2: US$ | P2: RD$ | Q2: US$ | R2: RD$ | S2: US$ | T2: RD$ | U2: US$ | V2: RD$ | W2: US$ | X2: RD$ | Y2: US$ | Z2: RD$ | AA2: US$ | AC2: Gastos Adicionales no contemplados
A3: CLARO | B3: ='[1]Gastos TC enero 2025'!C15 -> 5750.89 | D3: ='[1]Gastos TC febrero 2025'!C18 -> 5750.89 | F3: ='[1]Gastos TC marzo 2025'!C18 -> 5750.89 | H3: ='[1]Gastos TC abril 2025'!C13 -> 5750.89 | J3: ='[1]Gastos TC mayo 2025'!C5 -> 5750.89 | L3: ='[1]Gastos TC junio 2025'!C10 -> 5750.89 | N3: ='[1]Gastos TC julio 2025'!C13 -> 5750.89 | P3: ='[1]Gastos TC Agosto 2025'!C12 -> 5750.89 | R3: ='[1] Gastos TC Septiembre 2025'!C7 -> 5750.89 | T3: ='[1] Gastos TC Octubre 2025'!C14 -> 5728.05 | V3: ='[1] Gastos TC Noviembre 2025'!C15 -> 5750.89 | X3: ='[1] Gastos TC Diciembre 2025'!C8 -> 5750.89 | Z3: =+B3+D3+F3+H3+J3+L3+N3+P3+R3+T3+V3+X3 -> 68987.84 | AA3: =+C3+E3+G3+I3+K3+M3+O3+Q3+S3 -> 0 | AC3: Flores | AD3: =1000 -> 1000
A4: EDESUR | B4: ='[1]Gastos TC enero 2025'!C10 -> 72045.04 | D4: ='[1]Gastos TC febrero 2025'!C74 -> 35248.92 | F4: ='[1]Gastos TC marzo 2025'!C108+'[1]Gastos TC marzo 2025'!C109 -> 61771.26 | H4: ='[1]Gastos TC abril 2025'!C91 -> 1515.36 | J4: ='[1]Gastos TC mayo 2025'!C79 -> 31580.17 | L4: ='[1]Gastos TC junio 2025'!C74 -> 30849.55 | N4: ='[1]Gastos TC julio 2025'!C75 -> 31138.19 | P4: ='[1]Gastos TC Agosto 2025'!C73 -> 34511.67 | R4: ='[1] Gastos TC Septiembre 2025'!C76 -> 29870.27 | T4: ='[1] Gastos TC Octubre 2025'!C99 -> 27278.45 | V4: ='[1] Gastos TC Noviembre 2025'!C97 -> 36047.86 | X4: ='[1] Gastos TC Diciembre 2025'!C99 -> 36751.42 | Z4: =+B4+D4+F4+H4+J4+L4+N4+P4+R4+T4+V4+X4 -> 428608.16 | AA4: =+C4+E4+G4+I4+K4+M4+O4+Q4+S4 -> 0 | AC4: Super | AD4: =1729 -> 1729
A5: MANTENIMIENTO | B5: 30000 | D5: 30000 | F5: 30000 | H5: 31200 | J5: 31200 | L5: =J5 -> 31200 | N5: =L5 -> 31200 | P5: =N5 -> 31200 | R5: =P5 -> 31200 | T5: =R5 -> 31200 | V5: =T5 -> 31200 | X5: =V5 -> 31200 | Z5: =+B5+D5+F5+H5+J5+L5+N5+P5+R5+T5+V5+X5 -> 370800 | AA5: =+C5+E5+G5+I5+K5+M5+O5+Q5+S5 -> 0 | AC5: TOTAL | AD5: =SUM(AD3:AD4) -> 2729
A6: OTROS GASTOS CASA | B6: =1000+61106.32+1000 -> 63106.32 | D6: =6152.64+1000+1000 -> 8152.64 | F6: =6908.46+1000 -> 7908.46 | H6: =6828.9+1000+1000 -> 8828.9 | I6: =200 -> 200 | J6: =6500+5648.76+19300+1000 -> 32448.76 | L6: =6364.8+1000 -> 7364.8 | N6: =5144.88 -> 5144.88 | P6: =31200+2559.18+1555+5906.25+700 -> 41920.43 | R6: =16430.25+7034.31+1200 -> 24664.56 | T6: ='[1] Gastos TC Octubre 2025'!C105+'[1] Gastos TC Octubre 2025'!C106+5859.83+2400 -> 27979.83 | V6: =6830.12 -> 6830.12 | X6: =5785.12+15000+38940 -> 59725.12 | Z6: =+B6+D6+F6+H6+J6+L6+N6+P6+R6+T6+V6+X6 -> 294074.82 | AA6: =+C6+E6+G6+I6+K6+M6+O6+Q6+S6+U6+W6+Y6 -> 200
A7: GASTOS SUPERMERCADO | B7: ='[1]Gastos TC enero 2025'!D89+'[1]Gastos TC enero 2025'!D111+'[1]Gastos TC enero 2025'!D160+11400 -> 82163.7 | D7: ='[1]Gastos TC febrero 2025'!D67+'[1]Gastos TC febrero 2025'!D99+'[1]Gastos TC febrero 2025'!D138 -> 70390.7 | F7: ='[1]Gastos TC marzo 2025'!D95+'[1]Gastos TC marzo 2025'!D123+'[1]Gastos TC marzo 2025'!D167 -> 73356.15 | H7: ='[1]Gastos TC abril 2025'!D81+'[1]Gastos TC abril 2025'!D150+'[1]Gastos TC abril 2025'!D178+'[1]Gastos TC abril 2025'!D114+11400 -> 139227.44 | J7: ='[1]Gastos TC mayo 2025'!D67+'[1]Gastos TC mayo 2025'!D96+'[1]Gastos TC mayo 2025'!D120+'[1]Gastos TC mayo 2025'!D137+11600 -> 65611.6 | L7: ='[1]Gastos TC junio 2025'!D63+'[1]Gastos TC junio 2025'!D92+'[1]Gastos TC junio 2025'!D119+'[1]Gastos TC junio 2025'!D158+5291+600+2200+1200 -> 116222.47 | N7: ='[1]Gastos TC julio 2025'!D60+'[1]Gastos TC julio 2025'!D100+'[1]Gastos TC julio 2025'!D122+'[1]Gastos TC julio 2025'!D148+1200+600+2100+3500+1600 -> 49754.24 | P7: ='[1]Gastos TC Agosto 2025'!D59+'[1]Gastos TC Agosto 2025'!D93+'[1]Gastos TC Agosto 2025'!D126+'[1]Gastos TC Agosto 2025'!D152+11600+3000+6450+1500+700+1200 -> 46952.57 | R7: ='[1] Gastos TC Septiembre 2025'!D95+'[1] Gastos TC Septiembre 2025'!D111+'[1] Gastos TC Septiembre 2025'!D145 -> 67505.64 | T7: ='[1] Gastos TC Octubre 2025'!D87+'[1] Gastos TC Octubre 2025'!D129+'[1] Gastos TC Octubre 2025'!D150+'[1] Gastos TC Octubre 2025'!D175+11600 -> 80201.29 | V7: ='[1] Gastos TC Noviembre 2025'!D81+'[1] Gastos TC Noviembre 2025'!D138+'[1] Gastos TC Noviembre 2025'!D153+'[1] Gastos TC Noviembre 2025'!D188 -> 78133.63 | X7: ='[1] Gastos TC Diciembre 2025'!D75+'[1] Gastos TC Diciembre 2025'!D153+'[1] Gastos TC Diciembre 2025'!D175+'[1] Gastos TC Diciembre 2025'!D209 -> 60031.57 | Z7: =+B7+D7+F7+H7+J7+L7+N7+P7+R7+T7+V7+X7 -> 929551 | AA7: =+C7+E7+G7+I7+K7+M7+O7+Q7+S7 -> 0
A8: REMODELACIONES | K8: 8750 | L8: =360000+505000+100000-12000 -> 953000 | N8: =37083.86+3209.6+110918.4+15571.79+23418.56+7910.31+3650+49073.6+3650+24065.07+21800+32945.4+150000 -> 483296.59 | O8: =8769.6 -> 8769.6 | P8: =300000+15750+14225+21800-50000+55163.26+308800 -> 665738.26 | Q8: =580+2522.14-'[1]Gastos TC Agosto 2025'!C235 -> 6973.4 | R8: =62700+12000-10000+520157.5+'[1] Gastos TC Septiembre 2025'!C4+'[1] Gastos TC Septiembre 2025'!C61+'[1] Gastos TC Septiembre 2025'!C86+324080.66 -> 1017593.2 | S8: =8750-'[1] Gastos TC Septiembre 2025'!C211-'[1] Gastos TC Septiembre 2025'!C325-'[1] Gastos TC Septiembre 2025'!C331 -> 9150.11 | T8: =11000+6000+17500+49683.82+29123.1+21172+20000-5000-60000-5000-6000+'[1] Gastos TC Octubre 2025'!C13+'[1] Gastos TC Octubre 2025'!C16+'[1] Gastos TC Octubre 2025'!C17+'[1] Gastos TC Octubre 2025'!C30+'[1] Gastos TC Octubre 2025'!C79+'[1] Gastos TC Octubre 2025'!C86+'[1] Gastos TC Octubre 2025'!C95+'[1] Gastos TC Octubre 2025'!C96+'[1] Gastos TC Octubre 2025'!C98+'[1] Gastos TC Octubre 2025'!C107+'[1] Gastos TC Octubre 2025'!C111 -> 1692318.3 | V8: =-5000-5000-5000+4000+17500+15000+12000+323454.24+25085.71+'[1] Gastos TC Noviembre 2025'!C48+'[1] Gastos TC Noviembre 2025'!C49+'[1] Gastos TC Noviembre 2025'!C51+'[1] Gastos TC Noviembre 2025'!C59+'[1] Gastos TC Noviembre 2025'!C66+'[1] Gastos TC Noviembre 2025'!C110+'[1] Gastos TC Noviembre 2025'!C180 -> 1654160.6 | W8: 1702.73 | X8: ='[1] Gastos TC Diciembre 2025'!C48-8000+233290+15000+172180.29+64762.75-5000+15000+20000+10000+352838.34 -> 908816.38 | Y8: =-'[1] Gastos TC Diciembre 2025'!C258+3750+6172.78+8750 -> 21348.64 | Z8: =+B8+D8+F8+H8+J8+L8+N8+P8+R8+T8+V8+X8 -> 7374923.3 | AA8: =+C8+E8+G8+I8+K8+M8+O8+Q8+S8+U8+W8+Y8 -> 56694.48 | AB8: =Z8+(AA8*AA58) -> 10952345 | AC8: =AB8/61.8 -> 177222.41
A9: TOTAL GASTOS CASA | B9: =SUM(B3:B8) -> 253065.95 | C9: =SUM(C3:C8) -> 0 | D9: =SUM(D3:D8) -> 149543.15 | E9: =SUM(E3:E8) -> 0 | F9: =SUM(F3:F8) -> 178786.76 | H9: =SUM(H3:H8) -> 186522.59 | I9: =SUM(I3:I8) -> 200 | J9: =SUM(J3:J8) -> 166591.42 | K9: =SUM(K3:K8) -> 8750 | L9: =SUM(L3:L8) -> 1144387.7 | M9: =SUM(M3:M8) -> 0 | N9: =SUM(N3:N8) -> 606284.79 | O9: =SUM(O3:O8) -> 8769.6 | ... Y9: =SUM(Y3:Y8) -> 21348.64 | Z9: =+B9+D9+F9+H9+J9+L9+N9+P9+R9+T9+V9+X9 -> 9466945.1 | AA9: =+C9+E9+G9+I9+K9+M9+O9+Q9+S9+U9+W9+Y9 -> 56894.48
A10: COLEGIO/CAMP/CLASES | Z10: =+B10+D10+F10+H10+J10+L10+N10+P10+R10+T10+V10+X10 -> 0 | AA10: =+C10+E10+G10+I10+K10+M10+O10+Q10+S10 -> 0
A11: Graciela | B11: ='[1]Gastos TC enero 2025'!C76 -> 30200 | C11: 3972.5 | D11: 0 | E11: 21802.5 | F11: 26751 | H11: ='[1]Gastos TC abril 2025'!C57 -> 2000 | I11: =3722.5+250 -> 3972.5 | J11: =6000+1000+1500+3000 -> 11500 | L11: =3176 -> 3176 | P11: =2910+5800+800+1400+3000+1500 -> 15410 | R11: =10000+3000 -> 13000 | S11: 425 | T11: ='[1] Gastos TC Octubre 2025'!C51+'[1] Gastos TC Octubre 2025'!C124+3000 -> 20600 | V11: ='[1] Gastos TC Noviembre 2025'!C6+'[1] Gastos TC Noviembre 2025'!C68+'[1] Gastos TC Noviembre 2025'!C73+'[1] Gastos TC Noviembre 2025'!C136 -> 11750 | X11: ='[1] Gastos TC Diciembre 2025'!C95-6300+'[1] Gastos TC Diciembre 2025'!C108+'[1] Gastos TC Diciembre 2025'!C150+1000+7000-3500+5000 -> 32100 | Z11: =+B11+D11+F11+H11+J11+L11+N11+P11+R11+T11+V11+X11 -> 166487 | AA11: =+C11+E11+G11+I11+K11+M11+O11+Q11+S11+U11+W11+Y11 -> 30172.5
A12: Catalina | B12: 0 | C12: 3972.5 | D12: ='[1]Gastos TC febrero 2025'!C7 -> 2000 | E12: 21802.5 | F12: ='[1]Gastos TC marzo 2025'!C44+26751+5000+10000 -> 46751 | H12: ='[1]Gastos TC abril 2025'!C56 -> 3000 | I12: =3722.5+250 -> 3972.5 | J12: =3000+8700 -> 11700 | L12: ='[1]Gastos TC junio 2025'!C27+14980+5000-14980 -> 10000 | P12: =3000+4640+10000+800 -> 18440 | R12: =5000+10000 -> 15000 | T12: ='[1] Gastos TC Octubre 2025'!C55+10000 -> 11950 | V12: ='[1] Gastos TC Noviembre 2025'!C5+'[1] Gastos TC Noviembre 2025'!C37+8200 -> 17080 | X12: ='[1] Gastos TC Diciembre 2025'!C95-12600+'[1] Gastos TC Diciembre 2025'!C107+'[1] Gastos TC Diciembre 2025'!C109+10000+6000 -> 27300 | Z12: =+B12+D12+F12+H12+J12+L12+N12+P12+R12+T12+V12+X12 -> 163221 | AA12: =+C12+E12+G12+I12+K12+M12+O12+Q12+S12+U12+W12+Y12 -> 29747.5
A13: TOTAL GASTOS COLEGIO/CAMP/CLASES | B13: =SUM(B10:B12) -> 30200 | C13: =SUM(C11:C12) -> 7945 | D13: =SUM(D10:D12) -> 2000 | E13: =SUM(E10:E12) -> 43605 | F13: =SUM(F10:F12) -> 73502 | G13: =SUM(G10:G12) -> 0 | H13: =SUM(H10:H12) -> 5000 | I13: =SUM(I10:I12) -> 7945 | J13: =SUM(J11:J12) -> 23200 | K13: =SUM(K11:K12) -> 0 | L13: =SUM(L11:L12) -> 13176 | M13: =SUM(M11:M12) -> 0 | N13: =SUM(N11:N12) -> 0 | O13: =SUM(O11:O12) -> 0 | P13: =SUM(P10:P12) -> 33850 | Q13: =SUM(Q11:Q12) -> 0 | R13: =SUM(R10:R12) -> 28000 | S13: =SUM(S11:S12) -> 425 | T13: =SUM(T10:T12) -> 32550 | U13: =SUM(U10:U12) -> 0 | V13: =SUM(V10:V12) -> 28830 | W13: =SUM(W10:W12) -> 0 | X13: =SUM(X10:X12) -> 59400 | Y13: =SUM(Y10:Y12) -> 0 | Z13: =+B13+D13+F13+H13+J13+L13+N13+P13+R13+T13+V13+X13 -> 329708 | AA13: =+C13+E13+G13+I13+K13+M13+O13+Q13+S13+U13+W13+Y13 -> 59920
A14: EMPLEADOS PC
A15: EDUARD OZUNA | B15: ='[1]Gastos TC enero 2025'!C155 -> 1686.34 | D15: ='[1]Gastos TC febrero 2025'!C124 -> 1686.34 | F15: ='[1]Gastos TC marzo 2025'!C163 -> 1686.34 | H15: ='[1]Gastos TC abril 2025'!C143 -> 1686.34 | J15: ='[1]Gastos TC mayo 2025'!C117 -> 1875.5 | L15: ='[1]Gastos TC junio 2025'!C117 -> 1875.5 | N15: ='[1]Gastos TC julio 2025'!C115 -> 1875.5 | P15: ='[1]Gastos TC Agosto 2025'!C123 -> 1875.5 | R15: ='[1] Gastos TC Septiembre 2025'!C107 -> 1875.5 | T15: ='[1] Gastos TC Octubre 2025'!C146 -> 1875.5 | V15: ='[1] Gastos TC Noviembre 2025'!C148+6765+20000 -> 28640.5 | X15: ='[1] Gastos TC Diciembre 2025'!C186 -> 5850 | Z15: =+B15+D15+F15+H15+J15+L15+N15+P15+R15+T15+V15+X15 -> 52488.86 | AA15: =+C15+E15+G15+I15+K15+M15+O15+Q15+S15 -> 0
A16: CAROLIN MORENO | B16: 20000 | D16: =20000+10000 -> 30000 | F16: =20000-1000 -> 19000 | H16: =22000-1000-1000 -> 20000 | J16: =22000-1000-1000+5000 -> 25000 | L16: =22000+1500+3000+3000 -> 29500 | N16: 22000 | P16: =22000+4500+7000-2500-2500 -> 28500 | R16: =22000+5000+5000-2000 -> 30000 | T16: =22000+10000-1500-1500 -> 29000 | V16: =22000+10000-1500-1500 -> 29000 | X16: =22000+5000-1500+26000 -> 51500 | Z16: =+B16+D16+F16+H16+J16+L16+N16+P16+R16+T16+V16+X16 -> 333500 | AA16: =+C16+E16+G16+I16+K16+M16+O16+Q16+S16 -> 0
A17: PELARGIDA BATISTA (SONIA) | B17: 7000 | D17: 7000 | F17: 7000 | H17: 7000 | J17: 7000 | L17: 7000 | N17: 7000 | P17: 7000 | R17: 7000 | T17: 7000 | V17: 7000 | X17: =7000+7000 -> 14000 | Z17: =+B17+D17+F17+H17+J17+L17+N17+P17+R17+T17+V17+X17 -> 91000 | AA17: =+C17+E17+G17+I17+K17+M17+O17+Q17+S17 -> 0
A18: MARIA DELGADO (SALIDA 09/02/2025) | B18: 22000 | D18: 10731.47 | F18: 0 | H18: 0 | J18: 0 | Z18: =+B18+D18+F18+H18+J18+L18+N18+P18+R18+T18+V18+X18 -> 32731.47 | AA18: =+C18+E18+G18+I18+K18+M18+O18+Q18+S18 -> 0
A19: JEANIDALIA SUAREZ (SALIDA 30/05/2025) | B19: 22000 | D19: 24000 | F19: 24000 | H19: 24000 | J19: =10500+50000 -> 60500 | Z19: =+B19+D19+F19+H19+J19+L19+N19+P19+R19+T19+V19+X19 -> 154500 | AA19: =+C19+E19+G19+I19+K19+M19+O19+Q19+S19 -> 0
A20: MARIBEL CANDELARIO (SALIDA 29/08/2025) | B20: 0 | D20: 0 | F20: 0 | H20: =6250+3750 -> 10000 | J20: 22000 | L20: 22000 | N20: 22000 | P20: 22000 | R20: 7451.61 | Z20: =+B20+D20+F20+H20+J20+L20+N20+P20+R20+T20+V20+X20 -> 105451.61 | AA20: =+C20+E20+G20+I20+K20+M20+O20+Q20+S20 -> 0
A21: MELISSA RODRIGUEZ (SALIDA 28/10/2025) | R21: =11000+1000 -> 12000 | T21: =11000+2000 -> 13000 | Z21: =+B21+D21+F21+H21+J21+L21+N21+P21+R21+T21+V21+X21 -> 25000 | AA21: =+C21+E21+G21+I21+K21+M21+O21+Q21+S21 -> 0
A22: Limpieza Profunda Victor/Temporales | B22: 6000 | D22: 4500 | F22: 6000 | H22: 4500 | J22: 6000 | L22: 3000 | N22: 4500 | P22: 6000 | R22: 6000 | T22: =1500+1500+2000+1500 -> 6500 | V22: =3000+1500 -> 4500 | X22: =1500+1500+1500+1500+5000 -> 11000 | Z22: =+B22+D22+F22+H22+J22+L22+N22+P22+R22+T22+V22+X22 -> 68500 | AA22: =+C22+E22+G22+I22+K22+M22+O22+Q22+S22 -> 0
A23: TOTAL GASTOS EMPLEADOS | B23: =SUM(B15:B22) -> 78686.34 | C23: 0 | D23: =SUM(D15:D22) -> 77917.81 | E23: =SUM(E16:E17) -> 0 | F23: =SUM(F15:F22) -> 57686.34 | G23: =SUM(G15:G17) -> 0 | H23: =SUM(H15:H22) -> 67186.34 | I23: =SUM(I15:I17) -> 0 | J23: =SUM(J15:J22) -> 122375.5 | K23: =SUM(K15:K17) -> 0 | L23: =SUM(L15:L22) -> 63375.5 | M23: =SUM(M15:M17) -> 0 | N23: =SUM(N15:N22) -> 57375.5 | O23: =SUM(O15:O17) -> 0 | P23: =SUM(P15:P22) -> 65375.5 | Q23: =SUM(Q15:Q17) -> 0 | R23: =SUM(R15:R22) -> 64327.11 | S23: =SUM(S14:S203) -> 0 | T23: =SUM(T14:T22) -> 57375.5 | U23: =SUM(U16:U17) -> 0 | V23: =SUM(V14:V22) -> 69140.5 | X23: =SUM(X14:X22) -> 82350 | Y23: =SUM(Y15:Y22) -> 0 | Z23: =+B23+D23+F23+H23+J23+L23+N23+P23+R23+T23+V23+X23 -> 863171.94 | AA23: =+C23+E23+G23+I23+K23+M23+O23+Q23+S23 -> 0
A24: SEGUROS | Z24: =+B24+D24+F24+H24+J24+L24+N24+P24+R24 -> 0 | AA24: =+C24+E24+G24+I24+K24+M24+O24+Q24+S24 -> 0
A25: Póliza Sura Objetos Valiosos | B25: ='[1]Gastos TC enero 2025'!C40 -> 24942.65 | D25: ='[1]Gastos TC febrero 2025'!C76+'[1]Gastos TC febrero 2025'!C97 -> 50861.14 | R25: ='[1] Gastos TC Septiembre 2025'!C80 -> 42568.15 | T25: ='[1] Gastos TC Octubre 2025'!C115 -> 26154.77 | V25: 26318.57 | X25: ='[1] Gastos TC Diciembre 2025'!C115 -> 26601.12 | Z25: =+B25+D25+F25+H25+J25+L25+N25+P25+R25+T25+V25+X25 -> 197446.4 | AA25: =+C25+E25+G25+I25+K25+M25+O25+Q25+S25 -> 0
A26: Póliza La Colonial Salud Internacional | B26: 0 | C26: 2450 | S26: 3377.55 | U26: 3377.55 | W26: 3377.55 | Y26: 3377.55 | Z26: =+B26+D26+F26+H26+J26+L26+N26+P26+R26+T26+V26+X26 -> 0 | AA26: =+C26+E26+G26+I26+K26+M26+O26+Q26+S26+U26+W26+Y26 -> 15960.2
A27: Póliza Mapfre Incendio y líneas aliadas | B27: ='[1]Gastos TC enero 2025'!C39+'[1]Gastos TC enero 2025'!C108 -> 15502.39 | D27: ='[1]Gastos TC febrero 2025'!C96 -> 7875.19 | R27: ='[1] Gastos TC Septiembre 2025'!C82 -> 10447.19 | T27: ='[1] Gastos TC Octubre 2025'!C103 -> 10851.57 | V27: ='[1] Gastos TC Noviembre 2025'!C102 -> 10713.97 | X27: ='[1] Gastos TC Diciembre 2025'!C113 -> 10941.24 | Z27: =+B27+D27+F27+H27+J27+L27+N27+P27+R27+T27+V27+X27 -> 66331.55 | AA27: =+C27+E27+G27+I27+K27+M27+O27+Q27+S27+U27+W27+Y27 -> 0
A28: Pólizas de Vida JMPP/AMCR | I28: =-'[1]Gastos TC abril 2025'!C261-'[1]Gastos TC abril 2025'!C262 -> 7912 | M28: =-'[1]Gastos TC junio 2025'!C170+-'[1]Gastos TC junio 2025'!C171 -> 8572 | Z28: =+B28+D28+F28+H28+J28+L28+N28+P28+R28+T28 -> 0 | AA28: =+C28+E28+G28+I28+K28+M28+O28+Q28+S28+U28+W28+Y28 -> 16484
A29: TOTAL SEGUROS | B29: =SUM(B25:B28) -> 40445.04 | C29: =SUM(C26:C28) -> 2450 | D29: =SUM(D25:D28) -> 58736.33 | E29: =SUM(E24:E28) -> 0 | F29: =SUM(F25:F28) -> 0 | G29: =SUM(G25:G28) -> 0 | H29: =SUM(H25:H28) -> 0 | I29: =SUM(I25:I28) -> 7912 | J29: =SUM(J25:J28) -> 0 | K29: =SUM(K25:K28) -> 0 | L29: =SUM(L25:L28) -> 0 | M29: =SUM(M25:M28) -> 8572 | ... P29: =SUM(P25:P28) -> 0 | Q29: =SUM(Q24:Q28) -> 0 | R29: =SUM(R25:R28) -> 53015.34 | S29: =SUM(S24:S28) -> 3377.55 | T29: =SUM(T25:T28) -> 37006.34 | U29: =SUM(U24:U28) -> 3377.55 | V29: =SUM(V24:V28) -> 37032.54 | W29: =SUM(W25:W28) -> 3377.55 | X29: =SUM(X24:X28) -> 37542.36 | Y29: =SUM(Y24:Y28) -> 3377.55 | Z29: =+B29+D29+F29+H29+J29+L29+N29+P29+R29+T29+V29+X29 -> 263777.95 | AA29: =+C29+E29+G29+I29+K29+M29+O29+Q29+S29+U29+W29+Y29 -> 32444.2
A30: TARJETAS | Z30: =+B30+D30+F30+H30+J30+L30+N30+P30+R30 -> 0 | AA30: =+C30+E30+G30+I30+K30+M30+O30+Q30+S30 -> 0
A31: AMEX **4134 | B31: ='[1]Gastos TC enero 2025'!E112-'[1]Gastos TC enero 2025'!C97-'[1]Gastos TC enero 2025'!C98-'[1]Gastos TC enero 2025'!C108 -> 42771.54 | D31: ='[1]Gastos TC febrero 2025'!E100-'[1]2025'!D4-'[1]Gastos TC febrero 2025'!C79-'[1]Gastos TC febrero 2025'!C83-'[1]2025'!D25-D47-D27 -> 46884.72 | F31: ='[1]Gastos TC marzo 2025'!C123-'[1]Gastos TC marzo 2025'!C103-'[1]Gastos TC marzo 2025'!C108-'[1]Gastos TC marzo 2025'!C109-'[1]Gastos TC marzo 2025'!C110-F47 -> 46393.77 | H31: ='[1]Gastos TC abril 2025'!E115-'[1]Gastos TC abril 2025'!C87-'[1]Gastos TC abril 2025'!C89-'[1]Gastos TC abril 2025'!C91-'[1]Gastos TC abril 2025'!C92-'[1]Gastos TC abril 2025'!D114 -> 91362.8 | J31: ='[1]Gastos TC mayo 2025'!E97-'[1]Gastos TC mayo 2025'!C77-'[1]Gastos TC mayo 2025'!C79-'[1]Gastos TC mayo 2025'!D96 -> 65547.63 | K31: ='[1]Gastos TC mayo 2025'!C102-K46 -> 0 | L31: ='[1]Gastos TC junio 2025'!E93-'[1]Gastos TC junio 2025'!C69-'[1]Gastos TC junio 2025'!C74 -> 66131.3 | N31: ='[1]Gastos TC julio 2025'!E101-'[1]Gastos TC julio 2025'!C75-'[1]Gastos TC julio 2025'!C76 -> 144069.37 | P31: ='[1]Gastos TC Agosto 2025'!E94-'[1]Gastos TC Agosto 2025'!C73-'[1]Gastos TC Agosto 2025'!C76-'[1]Gastos TC Agosto 2025'!C77-'[1]Gastos TC Agosto 2025'!C80 -> 32490.61 | Q31: ='[1]Gastos TC Agosto 2025'!C103 -> 814.46 | R31: ='[1] Gastos TC Septiembre 2025'!E96-'[1] Gastos TC Septiembre 2025'!D95-'[1] Gastos TC Septiembre 2025'!C75-'[1] Gastos TC Septiembre 2025'!C76-'[1] Gastos TC Septiembre 2025'!C77-'[1] Gastos TC Septiembre 2025'!C80-'[1] Gastos TC Septiembre 2025'!C82-'[1] Gastos TC Septiembre 2025'!C84-'[1] Gastos TC Septiembre 2025'!C86-'[1] Gastos TC Septiembre 2025'!C89 -> 45544.75 | T31: ='[1] Gastos TC Octubre 2025'!E130-'[1] Gastos TC Octubre 2025'!D129-'[1] Gastos TC Octubre 2025'!C91-'[1] Gastos TC Octubre 2025'!C92-'[1] Gastos TC Octubre 2025'!C95-'[1] Gastos TC Octubre 2025'!C96-'[1] Gastos TC Octubre 2025'!C98-'[1] Gastos TC Octubre 2025'!C99-'[1] Gastos TC Octubre 2025'!C103-'[1] Gastos TC Octubre 2025'!C105-'[1] Gastos TC Octubre 2025'!C106-'[1] Gastos TC Octubre 2025'!C107-'[1] Gastos TC Octubre 2025'!C111-'[1] Gastos TC Octubre 2025'!C115-'[1] Gastos TC Octubre 2025'!C124-'[1] Gastos TC Octubre 2025'!C126 -> 69413.64 | V31: ='[1] Gastos TC Noviembre 2025'!E139-'[1] Gastos TC Noviembre 2025'!D138-'[1] Gastos TC Noviembre 2025'!C97-'[1] Gastos TC Noviembre 2025'!C100-'[1] Gastos TC Noviembre 2025'!C102-'[1] Gastos TC Noviembre 2025'!C110-'[1] Gastos TC Noviembre 2025'!C133-'[1] Gastos TC Noviembre 2025'!C134-'[1] Gastos TC Noviembre 2025'!C136 -> 144427.41 | X31: ='[1] Gastos TC Diciembre 2025'!E154-'[1] Gastos TC Diciembre 2025'!D153-'[1] Gastos TC Diciembre 2025'!C95-'[1] Gastos TC Diciembre 2025'!C98-'[1] Gastos TC Diciembre 2025'!C99-'[1] Gastos TC Diciembre 2025'!C107-'[1] Gastos TC Diciembre 2025'!C108-'[1] Gastos TC Diciembre 2025'!C109-'[1] Gastos TC Diciembre 2025'!C112-'[1] Gastos TC Diciembre 2025'!C113-'[1] Gastos TC Diciembre 2025'!C115-'[1] Gastos TC Diciembre 2025'!C116-'[1] Gastos TC Diciembre 2025'!C129-'[1] Gastos TC Diciembre 2025'!C130-'[1] Gastos TC Diciembre 2025'!C131-'[1] Gastos TC Diciembre 2025'!C142-'[1] Gastos TC Diciembre 2025'!C150-'[1] Gastos TC Diciembre 2025'!C151 -> 220159.45 | Z31: =+B31+D31+F31+H31+J31+L31+N31+P31+R31+T31+V31+X31 -> 1015197 | AA31: =+C31+E31+G31+I31+K31+M31+O31+Q31+S31+U31+W31+Y31 -> 814.46
A32: Black **1398 | B32: ='[1]Gastos TC enero 2025'!E90-'[1]Gastos TC enero 2025'!C10-'[1]Gastos TC enero 2025'!C15-'[1]Gastos TC enero 2025'!C23-'[1]Gastos TC enero 2025'!C29-'[1]Gastos TC enero 2025'!C30-'[1]Gastos TC enero 2025'!C34-'[1]Gastos TC enero 2025'!C35-'[1]Gastos TC enero 2025'!C39-'[1]Gastos TC enero 2025'!C40-'[1]Gastos TC enero 2025'!C76-'[1]Gastos TC enero 2025'!D89 -> 155950.99 | D32: ='[1]Gastos TC febrero 2025'!E68-'[1]Gastos TC febrero 2025'!D67-'[1]Gastos TC febrero 2025'!C7-'[1]Gastos TC febrero 2025'!C18 -> 141861.74 | F32: ='[1]Gastos TC marzo 2025'!E96-'[1]Gastos TC marzo 2025'!C18-'[1]Gastos TC marzo 2025'!D95-'[1]Gastos TC marzo 2025'!C44-F44-F41 -> 165126.19 | H32: ='[1]Gastos TC abril 2025'!E82-'[1]Gastos TC abril 2025'!C13-'[1]Gastos TC abril 2025'!D81-'[1]Gastos TC abril 2025'!C26-'[1]Gastos TC abril 2025'!C30-'[1]Gastos TC abril 2025'!C32-'[1]Gastos TC abril 2025'!C33-'[1]Gastos TC abril 2025'!C37-'[1]Gastos TC abril 2025'!C38-'[1]Gastos TC abril 2025'!C39-'[1]Gastos TC abril 2025'!C41-'[1]Gastos TC abril 2025'!C42-'[1]Gastos TC abril 2025'!C43-'[1]Gastos TC abril 2025'!C56-'[1]Gastos TC abril 2025'!C57-'[1]Gastos TC abril 2025'!C40 -> 120114.74 | J32: ='[1]Gastos TC mayo 2025'!C67-'[1]Gastos TC mayo 2025'!C5-'[1]Gastos TC mayo 2025'!C16-'[1]Gastos TC mayo 2025'!C19-'[1]Gastos TC mayo 2025'!C20-'[1]Gastos TC mayo 2025'!C34-'[1]Gastos TC mayo 2025'!C40 -> 84374.63 | L32: ='[1]Gastos TC junio 2025'!E64-'[1]Gastos TC junio 2025'!D63-'[1]Gastos TC junio 2025'!C10-'[1]Gastos TC junio 2025'!C15-'[1]Gastos TC junio 2025'!C27-'[1]Gastos TC junio 2025'!C29-'[1]Gastos TC junio 2025'!C34-'[1]Gastos TC junio 2025'!C39-'[1]Gastos TC junio 2025'!C41-'[1]Gastos TC junio 2025'!C42-'[1]Gastos TC junio 2025'!C47-'[1]Gastos TC junio 2025'!C52 -> 48004.77 | N32: ='[1]Gastos TC julio 2025'!E61-'[1]Gastos TC julio 2025'!C13-'[1]Gastos TC julio 2025'!D60-'[1]Gastos TC julio 2025'!C18-'[1]Gastos TC julio 2025'!C16-'[1]Gastos TC julio 2025'!C49 -> 128773.4 | P32: ='[1]Gastos TC Agosto 2025'!E60-'[1]Gastos TC Agosto 2025'!C5-'[1]Gastos TC Agosto 2025'!C12-'[1]Gastos TC Agosto 2025'!C44-'[1]Gastos TC Agosto 2025'!C46-'[1]Gastos TC Agosto 2025'!C47-'[1]Gastos TC Agosto 2025'!C50-'[1]Gastos TC Agosto 2025'!C51-'[1]Gastos TC Agosto 2025'!C54-'[1]Gastos TC Agosto 2025'!C56 -> 83216.49 | Q32: ='[1]Gastos TC Agosto 2025'!C65 -> 116 | R32: ='[1] Gastos TC Septiembre 2025'!E63-'[1] Gastos TC Septiembre 2025'!C4-'[1] Gastos TC Septiembre 2025'!C7-'[1] Gastos TC Septiembre 2025'!C37-'[1] Gastos TC Septiembre 2025'!C38-'[1] Gastos TC Septiembre 2025'!C39-'[1] Gastos TC Septiembre 2025'!C40-'[1] Gastos TC Septiembre 2025'!C41-'[1] Gastos TC Septiembre 2025'!C43-'[1] Gastos TC Septiembre 2025'!C47-'[1] Gastos TC Septiembre 2025'!C50-'[1] Gastos TC Septiembre 2025'!C52-'[1] Gastos TC Septiembre 2025'!C53-'[1] Gastos TC Septiembre 2025'!C54-'[1] Gastos TC Septiembre 2025'!C55-'[1] Gastos TC Septiembre 2025'!C56-'[1] Gastos TC Septiembre 2025'!C57-'[1] Gastos TC Septiembre 2025'!C59-'[1] Gastos TC Septiembre 2025'!C60-'[1] Gastos TC Septiembre 2025'!C61 -> 63428.32 | T32: ='[1] Gastos TC Octubre 2025'!E88-'[1] Gastos TC Octubre 2025'!D87-'[1] Gastos TC Octubre 2025'!C5-'[1] Gastos TC Octubre 2025'!C13-'[1] Gastos TC Octubre 2025'!C14-'[1] Gastos TC Octubre 2025'!C16-'[1] Gastos TC Octubre 2025'!C17-'[1] Gastos TC Octubre 2025'!C30-'[1] Gastos TC Octubre 2025'!C51-'[1] Gastos TC Octubre 2025'!C55-'[1] Gastos TC Octubre 2025'!C56-'[1] Gastos TC Octubre 2025'!C69-'[1] Gastos TC Octubre 2025'!C79-'[1] Gastos TC Octubre 2025'!C82-'[1] Gastos TC Octubre 2025'!C86 -> 173612 | V32: ='[1] Gastos TC Noviembre 2025'!E82-'[1] Gastos TC Noviembre 2025'!D81-'[1] Gastos TC Noviembre 2025'!C5-'[1] Gastos TC Noviembre 2025'!C6-'[1] Gastos TC Noviembre 2025'!C10-'[1] Gastos TC Noviembre 2025'!C15-'[1] Gastos TC Noviembre 2025'!C21-'[1] Gastos TC Noviembre 2025'!C25-'[1] Gastos TC Noviembre 2025'!C30-'[1] Gastos TC Noviembre 2025'!C32-'[1] Gastos TC Noviembre 2025'!C37-'[1] Gastos TC Noviembre 2025'!C48-'[1] Gastos TC Noviembre 2025'!C49-'[1] Gastos TC Noviembre 2025'!C51-'[1] Gastos TC Noviembre 2025'!C59-'[1] Gastos TC Noviembre 2025'!C66-'[1] Gastos TC Noviembre 2025'!C68-'[1] Gastos TC Noviembre 2025'!C69-'[1] Gastos TC Noviembre 2025'!C73-'[1] Gastos TC Noviembre 2025'!C79 -> 177010.74 | W32: ='[1] Gastos TC Noviembre 2025'!C87 -> 34.98 | X32: ='[1] Gastos TC Diciembre 2025'!E76-'[1] Gastos TC Diciembre 2025'!D75-'[1] Gastos TC Diciembre 2025'!C8-'[1] Gastos TC Diciembre 2025'!C48-'[1] Gastos TC Diciembre 2025'!C72 -> 119458.31 | Y32: ='[1] Gastos TC Diciembre 2025'!C82 -> 67.52 | Z32: =+B32+D32+F32+H32+J32+L32+N32+P32+R32+T32+V32+X32 -> 1460932.3 | AA32: =+C32+E32+G32+I32+K32+M32+O32+Q32+S32+U32+W32+Y32 -> 218.5
A33: TC Bank of America **7424 AMCR | C33: =-'[1]Gastos TC enero 2025'!C177 -> 3368.32 | E33: =-'[1]Gastos TC febrero 2025'!C196 -> 19151.17 | G33: =-'[1]Gastos TC marzo 2025'!C197 -> 3786.27 | I33: =-'[1]Gastos TC abril 2025'!C244-I41 -> 14969.78 | K33: =-'[1]Gastos TC mayo 2025'!C207 -> 7824.53 | M33: =-'[1]Gastos TC junio 2025'!C217-M28 -> 6669.5 | O33: =-'[1]Gastos TC julio 2025'!C178 -> 8912.99 | Q33: =-'[1]Gastos TC Agosto 2025'!C220 -> 23215.01 | S33: =-'[1] Gastos TC Septiembre 2025'!C213+'[1] Gastos TC Septiembre 2025'!C211+'[1] Gastos TC Septiembre 2025'!C203+'[1] Gastos TC Septiembre 2025'!C199 -> 3970.73 | U33: =-'[1] Gastos TC Octubre 2025'!C195+'[1] Gastos TC Octubre 2025'!C183 -> 1151.5 | W33: ='[1] Gastos TC Noviembre 2025'!C229+'[1] Gastos TC Noviembre 2025'!C223 -> 8878.2 | Y33: ='[1] Gastos TC Diciembre 2025'!C282+'[1] Gastos TC Diciembre 2025'!C258+'[1] Gastos TC Diciembre 2025'!C272+'[1] Gastos TC Diciembre 2025'!C249+'[1] Gastos TC Diciembre 2025'!C240 -> 8586.95 | Z33: =+B33+D33+F33+H33+J33+L33+N33+P33+R33+T33+V33+X33 -> 0 | AA33: =+C33+E33+G33+I33+K33+M33+O33+Q33+S33+U33+W33+Y33 -> 110484.95
A34: TC Bank of America **0180 JMPP | C34: =-'[1]Gastos TC enero 2025'!C250 -> 7868.58 | E34: =-'[1]Gastos TC febrero 2025'!C320 -> 21222.49 | G34: =-'[1]Gastos TC marzo 2025'!C253 -> 5261.55 | I34: =-'[1]Gastos TC abril 2025'!C350-I28 -> 15811.09 | K34: =-'[1]Gastos TC mayo 2025'!C346 -> 14996.46 | M34: =-'[1]Gastos TC junio 2025'!C292+'[1]Gastos TC junio 2025'!C228 -> 4578.82 | O34: =-'[1]Gastos TC julio 2025'!C238 -> 1191.52 | Q34: =-'[1]Gastos TC Agosto 2025'!C343+'[1]Gastos TC Agosto 2025'!C235+'[1]Gastos TC Agosto 2025'!C344 -> 18078.75 | S34: =-'[1] Gastos TC Septiembre 2025'!C335+'[1] Gastos TC Septiembre 2025'!C299+'[1] Gastos TC Septiembre 2025'!C302+'[1] Gastos TC Septiembre 2025'!C305+'[1] Gastos TC Septiembre 2025'!C325+'[1] Gastos TC Septiembre 2025'!C331 -> 11459.7 | U34: =-'[1] Gastos TC Octubre 2025'!C255+'[1] Gastos TC Octubre 2025'!C256+'[1] Gastos TC Octubre 2025'!C209+'[1] Gastos TC Octubre 2025'!C214+'[1] Gastos TC Octubre 2025'!C215+'[1] Gastos TC Octubre 2025'!C217+'[1] Gastos TC Octubre 2025'!C218+'[1] Gastos TC Octubre 2025'!C230+'[1] Gastos TC Octubre 2025'!C231 -> 10993.71 | W34: =-'[1] Gastos TC Noviembre 2025'!C303+'[1] Gastos TC Noviembre 2025'!C304 -> 5032.66 | Y34: ='[1] Gastos TC Diciembre 2025'!C396-'[1] Gastos TC Diciembre 2025'!C397 -> 12732.35 | Z34: =+B34+D34+F34+H34+J34+L34+N34+P34+R34+T34+V34+X34 -> 0 | AA34: =+C34+E34+G34+I34+K34+M34+O34+Q34+S34+U34+W34+Y34 -> 129227.68
A35: TC EDUARD AMEX **3440 | B35: ='[1]Gastos TC enero 2025'!D159-'[1]Gastos TC enero 2025'!D160 -> 5321.34 | D35: ='[1]Gastos TC febrero 2025'!D137-'[1]Gastos TC febrero 2025'!D138 -> 13952.21 | F35: ='[1]Gastos TC marzo 2025'!D166-'[1]Gastos TC marzo 2025'!D167-'[1]Gastos TC marzo 2025'!C163 -> 18544.8 | H35: ='[1]Gastos TC abril 2025'!D149-'[1]Gastos TC abril 2025'!D150-'[1]Gastos TC abril 2025'!C143 -> 6516.94 | J35: ='[1]Gastos TC mayo 2025'!D119-'[1]Gastos TC mayo 2025'!D120-'[1]Gastos TC mayo 2025'!C117 -> 5002.76 | L35: ='[1]Gastos TC junio 2025'!D118-'[1]Gastos TC junio 2025'!D119-'[1]Gastos TC junio 2025'!C117 -> 13675 | N35: ='[1]Gastos TC julio 2025'!D121-'[1]Gastos TC julio 2025'!D122-'[1]Gastos TC julio 2025'!C115 -> 6403.4 | P35: ='[1]Gastos TC Agosto 2025'!D125-'[1]Gastos TC Agosto 2025'!D126-'[1]Gastos TC Agosto 2025'!D112 -> 13521.33 | R35: ='[1] Gastos TC Septiembre 2025'!D110-'[1] Gastos TC Septiembre 2025'!D111 -> 7789.42 | T35: ='[1] Gastos TC Octubre 2025'!D149-'[1] Gastos TC Octubre 2025'!D150-'[1] Gastos TC Octubre 2025'!C146 -> 9823.99 | V35: ='[1] Gastos TC Noviembre 2025'!D152-'[1] Gastos TC Noviembre 2025'!D153-'[1] Gastos TC Noviembre 2025'!C148 -> 2770 | X35: ='[1] Gastos TC Diciembre 2025'!D174-'[1] Gastos TC Diciembre 2025'!D175 -> 9679.08 | Z35: =+B35+D35+F35+H35+J35+L35+N35+P35+R35+T35+V35+X35 -> 113000.27 | AA35: =+C35+E35+G35+I35+K35+M35+O35+Q35+S35+U35+W35+Y35 -> 0
A36: BHD INTERNATIONAL BANK **3801 | C36: ='[1]Gastos TC enero 2025'!C131 -> 926.23 | G36: 221.31 | I36: 0 | Y36: ='[1] Gastos TC Diciembre 2025'!C89 -> 250 | Z36: =+B36+D36+F36+H36+J36+L36+N36+P36+R36+T36+V36+X36 -> 0 | AA36: =+C36+E36+G36+I36+K36+M36+O36+Q36+S36+U36+W36+Y36 -> 1397.54
A37: TC EDUARD POPULAR **3652 | H37: ='[1]Gastos TC abril 2025'!D177-'[1]Gastos TC abril 2025'!D178 -> 14782.87 | J37: ='[1]Gastos TC mayo 2025'!D136-'[1]Gastos TC mayo 2025'!D137 -> 6066.9 | L37: ='[1]Gastos TC junio 2025'!D157-'[1]Gastos TC junio 2025'!D158 -> 28894.52 | N37: ='[1]Gastos TC julio 2025'!D147-'[1]Gastos TC julio 2025'!D148 -> 11766.6 | P37: ='[1]Gastos TC Agosto 2025'!D151-'[1]Gastos TC Agosto 2025'!D152-'[1]Gastos TC Agosto 2025'!C133 -> 28977.99 | R37: ='[1] Gastos TC Septiembre 2025'!D144-'[1] Gastos TC Septiembre 2025'!D145-'[1] Gastos TC Septiembre 2025'!C119-'[1] Gastos TC Septiembre 2025'!C120-'[1] Gastos TC Septiembre 2025'!C117-'[1] Gastos TC Septiembre 2025'!C136 -> 10462.94 | T37: ='[1] Gastos TC Octubre 2025'!D174-'[1] Gastos TC Octubre 2025'!D175-'[1] Gastos TC Octubre 2025'!C163-'[1] Gastos TC Octubre 2025'!C164-'[1] Gastos TC Octubre 2025'!C167 -> 6944.28 | V37: ='[1] Gastos TC Noviembre 2025'!D187-'[1] Gastos TC Noviembre 2025'!D188-'[1] Gastos TC Noviembre 2025'!C180-'[1] Gastos TC Noviembre 2025'!C184 -> 22644.85 | X37: ='[1] Gastos TC Diciembre 2025'!D208-'[1] Gastos TC Diciembre 2025'!D209-'[1] Gastos TC Diciembre 2025'!C186-'[1] Gastos TC Diciembre 2025'!C203 -> 19047.26 | Z37: =+B37+D37+F37+H37+J37+L37+N37+P37+R37+T37+V37+X37 -> 149588.21 | AA37: =+C37+E37+G37+I37+K37+M37+O37+Q37+S37+U37+W37+Y37 -> 0
A38: PAYPAL | C38: =31.77+22.33+13.77+114.97+19.37+19.99 -> 222.2 | E38: =19.99 -> 19.99 | G38: =16.42+16.42+15.61+8.49+1.14+548.91+10.19+15.89+7.93+19.99+6.56 -> 667.55 | I38: =16+44.82+4.92+104.97+27.24+9.43+2.17+105.93+19.99 -> 335.47 | K38: =7.04+411.95+19.99+363.8 -> 802.78 | M38: =34.47+7.02+19.99 -> 61.48 | O38: =260.01+19.99 -> 280 | Q38: =499.05+19.99 -> 519.04 | S38: =517.88+19.99 -> 537.87 | U38: =553.73+19.99 -> 573.72 | W38: =1417.76+348.29 -> 1766.05 | Z38: =+B38+D38+F38+H38+J38+L38+N38+P38+R38+T38+V38+X38 -> 0 | AA38: =+C38+E38+G38+I38+K38+M38+O38+Q38+S38+U38+W38+Y38 -> 5786.15
A39: TOTAL TARJETAS | B39: =SUM(B31:B38) -> 204043.87 | C39: =SUM(C31:C38) -> 12385.33 | D39: =SUM(D31:D38) -> 202698.67 | E39: =SUM(E31:E38) -> 40393.65 | F39: =SUM(F31:F38) -> 230064.76 | G39: =SUM(G31:G38) -> 9936.68 | H39: =SUM(H31:H38) -> 232777.35 | I39: =SUM(I31:I38) -> 31116.34 | ... L39: =SUM(L31:L38) -> 156705.59 | M39: =SUM(M31:M35) -> 11248.32 | N39: =SUM(N31:N38) -> 291012.77 | O39: =SUM(O31:O38) -> 10384.51 | P39: =SUM(P31:P38) -> 158206.42 | Q39: =SUM(Q31:Q38) -> 42743.26 | R39: =SUM(R31:R38) -> 127225.43 | S39: =SUM(S30:S38) -> 15968.3 | T39: =SUM(T31:T38) -> 259793.91 | U39: =SUM(U30:U38) -> 12718.93 | V39: =SUM(V31:V38) -> 346853 | W39: =SUM(W30:W38) -> 15711.89 | X39: =SUM(X30:X38) -> 368344.1 | Y39: =SUM(Y30:Y38) -> 21636.82 | Z39: =+B39+D39+F39+H39+J39+L39+N39+P39+R39+T39+V39+X39 -> 2738717.8 | AA39: =+C39+E39+G39+I39+K39+M39+O39+Q39+S39+U39+W39+Y39 -> 247867.8 | AB39: =Z39+(AA39*AA58) -> 18379176
A40: VARIOS | Z40: =+B40+D40+F40+H40+J40+L40+N40+P40+R40 -> 0 | AA40: =+C40+E40+G40+I40+K40+M40+O40+Q40+S40 -> 0
...

Sheet 2026
B1: 46023 | D1: 46054 | F1: 46082 | H1: 46113 | J1: 46143 | L1: 46174 | N1: 46204 | P1: 46235 | R1: 46266 | T1: 46296 | V1: 46327 | X1: 46357 | Z1: TOTAL
A2: CASA | B2: RD$ | C2: US$ | D2: RD$ | E2: US$ | F2: RD$ | G2: US$ | H2: RD$ | I2: US$ | J2: RD$ | K2: US$ | L2: RD$ | M2: US$ | N2: RD$ | O2: US$ | P2: RD$ | Q2: US$ | R2: RD$ | S2: US$ | T2: RD$ | U2: US$ | V2: RD$ | W2: US$ | X2: RD$ | Y2: US$ | Z2: RD$ | AA2: US$ | AC2: Gastos Adicionales no contemplados
A3: CLARO | Z3: =+B3+D3+F3+H3+J3+L3+N3+P3+R3+T3+V3+X3 -> 0 | AA3: =+C3+E3+G3+I3+K3+M3+O3+Q3+S3 -> 0 | AC3: Flores | AD3: =1000 -> 1000
A4: EDESUR | AA4: =+C4+E4+G4+I4+K4+M4+O4+Q4+S4 -> 0 | AC4: Super | AD4: =1729 -> 1729
A5: MANTENIMIENTO | AA5: =+C5+E5+G5+I5+K5+M5+O5+Q5+S5 -> 0 | AC5: TOTAL | AD5: =SUM(AD3:AD4) -> 2729
A6: OTROS GASTOS CASA | AA6: =+C6+E6+G6+I6+K6+M6+O6+Q6+S6+U6+W6+Y6 -> 0
A7: GASTOS SUPERMERCADO | AA7: =+C7+E7+G7+I7+K7+M7+O7+Q7+S7 -> 0
A8: REMODELACIONES | AA8: =+C8+E8+G8+I8+K8+M8+O8+Q8+S8+U8+W8+Y8 -> 0
A9: TOTAL GASTOS CASA | B9: =SUM(B3:B8) -> 0 | C9: =SUM(C3:C8) -> 0 | D9: =SUM(D3:D8) -> 0 | E9: =SUM(E3:E8) -> 0 | F9: =SUM(F3:F8) -> 0 | H9: =SUM(H3:H8) -> 0 | I9: =SUM(I3:I8) -> 0 | J9: =SUM(J3:J8) -> 0 | K9: =SUM(K3:K8) -> 0 | L9: =SUM(L3:L8) -> 0 | M9: =SUM(M3:M8) -> 0 | N9: =SUM(N3:N8) -> 0 | O9: =SUM(O3:O8) -> 0 | ... Y9: =SUM(Y3:Y8) -> 0 | Z9: =+B9+D9+F9+H9+J9+L9+N9+P9+R9+T9+V9+X9 -> 0 | AA9: =+C9+E9+G9+I9+K9+M9+O9+Q9+S9+U9+W9+Y9 -> 0
A10: COLEGIO/CAMP/CLASES | Z10: =+B10+D10+F10+H10+J10+L10+N10+P10+R10+T10+V10+X10 -> 0 | AA10: =+C10+E10+G10+I10+K10+M10+O10+Q10+S10 -> 0
A11: Graciela | Z11: =+B11+D11+F11+H11+J11+L11+N11+P11+R11+T11+V11+X11 -> 0 | AA11: =+C11+E11+G11+I11+K11+M11+O11+Q11+S11+U11+W11+Y11 -> 0
A12: Catalina | Z12: =+B12+D12+F12+H12+J12+L12+N12+P12+R12+T12+V12+X12 -> 0 | AA12: =+C12+E12+G12+I12+K12+M12+O12+Q12+S12+U12+W12+Y12 -> 0
A13: TOTAL GASTOS COLEGIO/CAMP/CLASES | B13: =SUM(B10:B12) -> 0 | C13: =SUM(C11:C12) -> 0 | D13: =SUM(D10:D12) -> 0 | E13: =SUM(E10:E12) -> 0 | F13: =SUM(F10:F12) -> 0 | G13: =SUM(G10:G12) -> 0 | H13: =SUM(H10:H12) -> 0 | I13: =SUM(I10:I12) -> 0 | J13: =SUM(J11:J12) -> 0 | K13: =SUM(K11:K12) -> 0 | L13: =SUM(L11:L12) -> 0 | M13: =SUM(M11:M12) -> 0 | N13: =SUM(N11:N12) -> 0 | O13: =SUM(O11:O12) -> 0 | P13: =SUM(P10:P12) -> 0 | Q13: =SUM(Q11:Q12) -> 0 | R13: =SUM(R10:R12) -> 0 | S13: =SUM(S11:S12) -> 0 | T13: =SUM(T10:T12) -> 0 | U13: =SUM(U10:U12) -> 0 | V13: =SUM(V10:V12) -> 0 | W13: =SUM(W10:W12) -> 0 | X13: =SUM(X10:X12) -> 0 | Y13: =SUM(Y10:Y12) -> 0 | Z13: =+B13+D13+F13+H13+J13+L13+N13+P13+R13+T13+V13+X13 -> 0 | AA13: =+C13+E13+G13+I13+K13+M13+O13+Q13+S13+U13+W13+Y13 -> 0
A14: EMPLEADOS PC
A15: EDUARD OZUNA | AA15: =+C15+E15+G15+I15+K15+M15+O15+Q15+S15 -> 0
A16: CAROLIN MORENO | AA16: =+C16+E16+G16+I16+K16+M16+O16+Q16+S16 -> 0
A17: LEIDA GUZMAN
A18: PELARGIDA BATISTA (SONIA) | AA18: =+C18+E18+G18+I18+K18+M18+O18+Q18+S18 -> 0
A19: Limpieza Profunda Victor/Temporales | AA19: =+C19+E19+G19+I19+K19+M19+O19+Q19+S19 -> 0
A20: TOTAL GASTOS EMPLEADOS | B20: =SUM(B15:B19) -> 0 | C20: 0 | D20: =SUM(D15:D19) -> 0 | E20: =SUM(E16:E18) -> 0 | F20: =SUM(F15:F19) -> 0 | G20: =SUM(G15:G18) -> 0 | H20: =SUM(H15:H19) -> 0 | I20: =SUM(I15:I18) -> 0 | J20: =SUM(J15:J19) -> 0 | K20: =SUM(K15:K18) -> 0 | L20: =SUM(L15:L19) -> 0 | M20: =SUM(M15:M18) -> 0 | N20: =SUM(N15:N19) -> 0 | O20: =SUM(O15:O18) -> 0 | P20: =SUM(P15:P19) -> 0 | Q20: =SUM(Q15:Q18) -> 0 | R20: =SUM(R15:R19) -> 0 | S20: =SUM(S14:S200) -> 0 | T20: =SUM(T14:T19) -> 0 | U20: =SUM(U16:U18) -> 0 | V20: =SUM(V14:V19) -> 0 | X20: =SUM(X14:X19) -> 0 | Y20: =SUM(Y15:Y19) -> 0 | Z20: =+B20+D20+F20+H20+J20+L20+N20+P20+R20+T20+V20+X20 -> 0 | AA20: =+C20+E20+G20+I20+K20+M20+O20+Q20+S20 -> 0
A21: SEGUROS | AA21: =+C21+E21+G21+I21+K21+M21+O21+Q21+S21 -> 0
A22: Póliza Sura Objetos Valiosos | AA22: =+C22+E22+G22+I22+K22+M22+O22+Q22+S22 -> 0
A23: Póliza La Colonial Salud Internacional | AA23: =+C23+E23+G23+I23+K23+M23+O23+Q23+S23+U23+W23+Y23 -> 0
A24: Póliza Mapfre Incendio y líneas aliadas | AA24: =+C24+E24+G24+I24+K24+M24+O24+Q24+S24+U24+W24+Y24 -> 0
A25: Pólizas de Vida JMPP/AMCR | AA25: =+C25+E25+G25+I25+K25+M25+O25+Q25+S25+U25+W25+Y25 -> 0
A26: TOTAL SEGUROS | B26: =SUM(B22:B25) -> 0 | C26: =SUM(C23:C25) -> 0 | D26: =SUM(D22:D25) -> 0 | E26: =SUM(E21:E25) -> 0 | F26: =SUM(F22:F25) -> 0 | G26: =SUM(G22:G25) -> 0 | H26: =SUM(H22:H25) -> 0 | I26: =SUM(I22:I25) -> 0 | J26: =SUM(J22:J25) -> 0 | K26: =SUM(K22:K25) -> 0 | L26: =SUM(L22:L25) -> 0 | M26: =SUM(M22:M25) -> 0 | ... P26: =SUM(P22:P25) -> 0 | Q26: =SUM(Q21:Q25) -> 0 | R26: =SUM(R22:R25) -> 0 | S26: =SUM(S21:S25) -> 0 | T26: =SUM(T22:T25) -> 0 | U26: =SUM(U21:U25) -> 0 | V26: =SUM(V21:V25) -> 0 | W26: =SUM(W22:W25) -> 0 | X26: =SUM(X21:X25) -> 0 | Y26: =SUM(Y21:Y25) -> 0 | Z26: =+B26+D26+F26+H26+J26+L26+N26+P26+R26+T26+V26+X26 -> 0 | AA26: =+C26+E26+G26+I26+K26+M26+O26+Q26+S26+U26+W26+Y26 -> 0
A27: TARJETAS | AA27: =+C27+E27+G27+I27+K27+M27+O27+Q27+S27 -> 0
A28: AMEX **4134 | AA28: =+C28+E28+G28+I28+K28+M28+O28+Q28+S28+U28+W28+Y28 -> 0
A29: Black **1398 | AA29: =+C29+E29+G29+I29+K29+M29+O29+Q29+S29+U29+W29+Y29 -> 0
A30: TC Bank of America **7424 AMCR | AA30: =+C30+E30+G30+I30+K30+M30+O30+Q30+S30+U30+W30+Y30 -> 0
A31: TC Bank of America **0180 JMPP | AA31: =+C31+E31+G31+I31+K31+M31+O31+Q31+S31+U31+W31+Y31 -> 0
A32: TC EDUARD AMEX **3440 | AA32: =+C32+E32+G32+I32+K32+M32+O32+Q32+S32+U32+W32+Y32 -> 0
A33: BHD INTERNATIONAL BANK **3801 | AA33: =+C33+E33+G33+I33+K33+M33+O33+Q33+S33+U33+W33+Y33 -> 0
A34: TC CCN POPULAR **3652 | AA34: =+C34+E34+G34+I34+K34+M34+O34+Q34+S34+U34+W34+Y34 -> 0
A35: PAYPAL | AA35: =+C35+E35+G35+I35+K35+M35+O35+Q35+S35+U35+W35+Y35 -> 0
A36: TOTAL TARJETAS | B36: =SUM(B28:B35) -> 0 | C36: =SUM(C28:C35) -> 0 | D36: =SUM(D28:D35) -> 0 | E36: =SUM(E28:E35) -> 0 | F36: =SUM(F28:F35) -> 0 | G36: =SUM(G28:G35) -> 0 | H36: =SUM(H28:H35) -> 0 | I36: =SUM(I28:I35) -> 0 | ... L36: =SUM(L28:L35) -> 0 | M36: =SUM(M28:M32) -> 0 | N36: =SUM(N28:N35) -> 0 | O36: =SUM(O28:O35) -> 0 | P36: =SUM(P28:P35) -> 0 | Q36: =SUM(Q28:Q35) -> 0 | R36: =SUM(R28:R35) -> 0 | S36: =SUM(S27:S35) -> 0 | T36: =SUM(T28:T35) -> 0 | U36: =SUM(U27:U35) -> 0 | V36: =SUM(V28:V35) -> 0 | W36: =SUM(W27:W35) -> 0 | X36: =SUM(X27:X35) -> 0 | Y36: =SUM(Y27:Y35) -> 0 | Z36: =+B36+D36+F36+H36+J36+L36+N36+P36+R36+T36+V36+X36 -> 0 | AA36: =+C36+E36+G36+I36+K36+M36+O36+Q36+S36+U36+W36+Y36 -> 0
A37: VARIOS | AA37: =+C37+E37+G37+I37+K37+M37+O37+Q37+S37 -> 0
A38: REGALOS | AA38: =+C38+E38+G38+I38+K38+M38+O38+Q38+S38+U38+W38+Y38 -> 0
A39: CONSUMOS MÉDICOS | AA39: =+C39+E39+G39+I39+K39+M39+O39+Q39+S39+U39+W39+Y39 -> 0
A40: VEHICULO | AA40: =+C40+E40+G40+I40+K40+M40+O40+Q40+S40+U40+W40+Y40 -> 0
...

Sheet Gastos TC enero 2026
A2: TC Popular | G2: DESGLOSE | H2: MONTOS
A3: FECHAS | B3: DESCRIPCION DE TRANSACCION | C3: MONTOS | D3: SUPERMERCADO | E3: PAGOS | G3: RESTAURANTE | H3: =C5+C6+C8+C9+C10+C17+C18+C22+C24+C26+C29+C32+C33+C38+C39+C40+C46+C53+C57+C87+C93+C96+C99+C100+C103+C106+C109+C116 -> 72447.7
A4: 45978 | B4: PEDIDOS YA TIPS | C4: 75 | G4: REVERSE | H4: =C84+C28+C47+C90+C97+C102+C108+C110+C111+C114 -> 32225
A5: 45979 | B5: PEDIDOS YA | C5: 1053.4 | G5: LAVANDERIA | H5: =C159 -> 5103.5
A6: 45979 | B6: ZEPHYROS YOGURT ICE CR | C6: 650 | G6: VINOS | H6: 0
A7: 45980 | B7: PEDIDOS YA TIPS | C7: 30 | G7: FLORISTERIA | H7: =C143+C151 -> 1644
A8: 45980 | B8: RESTAURANT SAMURAI | C8: 8938.5 | G8: TRAVEL CREDIT | H8: 0
A9: 45980 | B9: STARBUCKS LINCOLN | C9: 1156.4
A10: 45981 | B10: PEDIDOS YA | C10: 680
A11: 45982 | B11: CLARO P REC 8095408659 | C11: 5750.89
A12: 45986 | B12: HS AGIL TV | C12: 73662.18 | F12: APM
A13: 45986 | B13: HS AGIL TV | C13: 57006.87 | F13: APM
A14: 45989 | B14: PedidosYa*Propina | C14: 75 | F14: Reembolsado por CA
A15: 45990 | B15: PedidosYa*Saralinas Wh | C15: 961
A16: 45990 | B16: FARMABLUE | C16: 13259.17 | F16: Ozempic
A17: 45990 | B17: MAREA RESTAURANTE | C17: 1285.76
A18: 45990 | B18: PASTRY | C18: 140
A19: 45990 | B19: CALL CENTER PEAJE | C19: 3000
A20: 45990 | B20: CITY MARKET | D20: 2349.15
A21: 45992 | B21: PedidosYa*Propina | C21: 75
A22: 45992 | B22: MAREA RESTAURANTE | C22: 8538.24
A23: 45993 | B23: PedidosYa*Propina | C23: 75
A24: 45993 | B24: PedidosYa*Man Up Cook | C24: 3145
A25: 45993 | B25: Uber Rides -* Uber Rides | C25: 395
A26: 45994 | B26: PedidosYa*Mar | C26: 986.8
A27: 45995 | B27: SM NACIONAL METRO PLZA | D27: 1288.45
A28: 45995 | B28: Reverse | C28: 8305
A29: 45995 | B29: STARBUCKS LINCOLN | C29: 944
A30: 45996 | B30: Ministerio de relacion | C30: 2480 | F30: Apostillar doc
A31: 45996 | B31: Carol App-WB | C31: 1083.98
A32: 45999 | B32: PedidosYa*Pizza hut Lo | C32: 1815
A33: 45999 | B33: Mdconalds S Sarasota | C33: 3430
A34: 45999 | B34: PedidosYa*Propina | C34: 75
A35: 46000 | B35: FARMABLUE | C35: 23401.45 | F35: Ozempic y atrolip
A36: 46000 | B36: FARMABLUE | C36: 3751.65 | F36: Desodorantes
A37: 46001 | B37: Pago Via Internet | E37: -174120.35
A38: 46002 | B38: STARBUCKS LINCOLN | C38: 1038.4
A39: 46003 | B39: Wu Asian Cuisine | C39: 2472
A40: 46003 | B40: Krispy Kreme Churchill | C40: 860
A41: 46003 | B41: Gdos Tecnologia D Cons | C41: 1888
...
